<?xml version="1.0"?>
<robot name="/* robot_name */">

  <material name="blue">
    <color rgba="0 0 0.8 1"/>
  </material>

  <material name="white">
    <color rgba="1 1 1 1"/>
  </material>


  <link name="base_link">
    <visual>
      <geometry>
        <cylinder length="0.2" radius="0.2"/>
      </geometry>
      <material name="blue"/>
    </visual>
   </link>

  <link name="base_link2">
    <visual>
      <geometry>
        <cylinder length="0.2" radius="0.2"/>
      </geometry>
      <material name="blue"/>
    </visual>
  </link>

  
    <joint name="pitch" type="continuous">
    <parent link="base_link"/>
    <child link="base_link2"/>
    <axis xyz="-1.0 0.0 0.0"/>
    <origin xyz="0 0 0.1"/>
  </joint>

  <link name="base_link3">
    <visual>
      <geometry>
        <cylinder length="0.2" radius="0.2"/>
      </geometry>
      <material name="blue"/>
    </visual>
    </link>

  <joint name="yaw" type="continuous">
    <parent link="base_link2"/>
    <child link="base_link3"/>
    <axis xyz="0.0 1.0 0.0"/>
    <origin xyz="0 0 0.1"/>
  </joint>

  <link name="head">
    <visual>
      <geometry>
        <mesh filename="package://IMU_ADQ_pck/urdf/mesh/human-head-simplified.dae" scale="0.008 0.008 0.008"/>
      </geometry>
      <origin rpy="0 0 0" xyz="0 0 0.3"/>
      <material name="white"/>
    </visual>
  </link>


  <joint name="roll" type="continuous">
    <parent link="base_link3"/>
    <child link="head"/>
    <origin xyz="0 0 1.0"/>
    <axis xyz="0.0 0.0 1.0"/>
  </joint>

</robot>
